# Translations template for glance.
# Copyright (C) 2014 ORGANIZATION
# This file is distributed under the same license as the glance project.
#
# Translators:
# Maxime COQUEREL <max.coquerel@gmail.com>, 2014
msgid ""
msgstr ""
"Project-Id-Version: Glance\n"
"Report-Msgid-Bugs-To: EMAIL@ADDRESS\n"
"POT-Creation-Date: 2014-11-21 06:05+0000\n"
"PO-Revision-Date: 2014-11-03 10:00+0000\n"
"Last-Translator: openstackjenkins <jenkins@openstack.org>\n"
"Language-Team: French (http://www.transifex.com/projects/p/glance/language/"
"fr/)\n"
"Language: fr\n"
"MIME-Version: 1.0\n"
"Content-Type: text/plain; charset=UTF-8\n"
"Content-Transfer-Encoding: 8bit\n"
"Generated-By: Babel 1.3\n"
"Plural-Forms: nplurals=2; plural=(n > 1);\n"

#: glance/location.py:390
#, python-format
msgid ""
"Glance tried all active locations to get data for image %s but all have "
"failed."
msgstr ""

#: glance/scrubber.py:167
#, python-format
msgid "%s file can not be read."
msgstr "Le fichier %s ne peut pas etre lu."

#: glance/scrubber.py:190
#, python-format
msgid "%s file can not be wrote."
msgstr "Le fichier %s ne peut pas etre écrit."

#: glance/scrubber.py:516
#, python-format
msgid "Can not %(op)s scrub jobs from queue: %(err)s"
msgstr ""

#: glance/scrubber.py:617
#, python-format
msgid "%s file can not be created."
msgstr "Le fichier %s ne peut pas etre créé"

#: glance/api/common.py:53
#, python-format
msgid ""
"An error occurred reading from backend storage for image %(image_id)s: "
"%(err)s"
msgstr ""
"Une erreur s'est produite pendant le stockage backend de l'image "
"%(image_id)s : %(err)s "

#: glance/api/common.py:59
#, python-format
msgid ""
"Backend storage for image %(image_id)s disconnected after writing only "
"%(bytes_written)d bytes"
msgstr ""
"Le stockage d'arrière plan pour l'image %(image_id)s s'est déconnecté après "
"l'écriture de seulement %(bytes_written)d octets "

#: glance/api/common.py:90
#, python-format
msgid "An error occurred during image.send notification: %(err)s"
msgstr "Une erreur s'est produite lors de la notification image.send : %(err)s"

#: glance/api/common.py:118
#, python-format
msgid "Invalid value for option user_storage_quota: %(users_quota)s"
msgstr ""

#: glance/api/middleware/cache.py:169
#, python-format
msgid ""
"Image cache contained image file for image '%s', however the registry did "
"not contain metadata for that image!"
msgstr ""
"Le cache d'image contenait un fichier image pour l'image '%s', néanmoins le "
"registre ne contenait pas de métadonnées pour cette image ! "

#: glance/api/middleware/cache.py:268
#, python-format
msgid "could not find %s"
msgstr "impossible de trouver %s"

#: glance/api/middleware/cache.py:287
msgid "Checksum header is missing."
msgstr "L'en-tête de total de contrôle est manquant."

#: glance/api/v1/images.py:606
#, python-format
msgid "Copy from external source '%(scheme)s' failed for image: %(image)s"
msgstr ""
"Echec de copie depuis la source externe '%(scheme)s' pour l'image: %(image)s"

#: glance/api/v1/upload_utils.py:77
#, python-format
msgid "Unable to kill image %(id)s: "
msgstr "Impossible de supprimer l'image %(id)s :"

#: glance/api/v1/upload_utils.py:248
#, python-format
msgid "Received HTTP error while uploading image %s"
msgstr "Une erreur HTTP a été reçu lors du chargement de l'image %s"

#: glance/api/v2/image_data.py:59
#, python-format
msgid "Unable to restore image %(image_id)s: %(e)s"
msgstr "Impossible de restaurer l'image %(image_id)s: %(e)s"

#: glance/api/v2/image_data.py:155
msgid "Failed to upload image data due to HTTP error"
msgstr ""
"Echec de téléchargement des données de l'image en raison d'une erreur HTTP"

#: glance/api/v2/image_data.py:160
msgid "Failed to upload image data due to internal error"
msgstr ""
"Echec de téléchargement des données de l'image en raison d'une erreur interne"

#: glance/api/v2/metadef_namespaces.py:188
#, python-format
msgid "Failed to delete namespace %(namespace)s "
msgstr "Echec lors de la suppresion du namespace %(namespace)s"

#: glance/api/v2/metadef_resource_types.py:125
#: glance/tests/functional/v2/test_metadef_resourcetypes.py:128
#, python-format
msgid "Failed to find resource type %(resourcetype)s to delete"
msgstr "Echec pour trouver le type de ressource %(resourcetype)s a supprimer"

#: glance/async/__init__.py:67
msgid ""
"This execution of Tasks is not setup. Please consult the project "
"documentation for more information on the executors available."
msgstr ""

#: glance/async/__init__.py:71
msgid "Internal error occurred while trying to process task."
msgstr "Erreur interne s'est produite lors du traitement de la tâche ."

#: glance/common/store_utils.py:68
#, python-format
msgid "Failed to delete image %(image_id)s from store: %(exc)s"
msgstr "Echec de supprésion de l'image %(image_id)s depuis le magasin: %(exc)s"

#: glance/common/scripts/__init__.py:40
#, python-format
msgid ""
"This task type %(task_type)s is not supported by the current deployment of "
"Glance. Please refer the documentation provided by OpenStack or your "
"operator for more information."
msgstr ""

#: glance/common/scripts/__init__.py:50
#, python-format
msgid "Failed to save task %(task_id)s in DB as task_repo is %(task_repo)s"
msgstr ""

#: glance/common/scripts/utils.py:46
#, python-format
msgid "Task not found for task_id %s"
msgstr "Tache non trouvé pour  task_id %s"

#: glance/db/sqlalchemy/metadata.py:128
#, python-format
msgid "Json schema files not found in %s. Aborting."
msgstr ""

#: glance/db/sqlalchemy/migrate_repo/versions/015_quote_swift_credentials.py:62
#: glance/db/sqlalchemy/migrate_repo/versions/017_quote_encrypted_swift_credentials.py:96
#, python-format
msgid "Invalid store uri for image: %(image_id)s. Details: %(reason)s"
msgstr "uri magasin non valide pour image: %(image_id)s. Details: %(reason)s"

#: glance/domain/__init__.py:472
#, python-format
msgid "Failed to load the %s executor provided in the config."
msgstr ""

#: glance/image_cache/__init__.py:268
#, python-format
msgid ""
"Exception encountered while tee'ing image '%(image_id)s' into cache: "
"%(error)s. Continuing with response."
msgstr ""

#: glance/image_cache/drivers/sqlite.py:397
#, python-format
msgid "Error executing SQLite call. Got error: %s"
msgstr "Erreur lors de l'exécution de l'appel SQLite. Erreur obtenue : %s"

#: glance/image_cache/drivers/xattr.py:109
#, python-format
msgid ""
"The device housing the image cache directory %(image_cache_dir)s does not "
"support xattr. It is likely you need to edit your fstab and add the "
"user_xattr option to the appropriate line for the device housing the cache "
"directory."
msgstr ""
"L'unité hébergeant le répertoire de cache d'image %(image_cache_dir)s ne "
"prend pas en charge xattr. Vous devez probablement éditer votre fstab et "
"ajouter l'option user_xattr sur la ligne appropriée de l'unité hébergeant le "
"répertoire de cache."

#: glance/openstack/common/lockutils.py:117
#, python-format
msgid "Could not release the acquired lock `%s`"
msgstr "Impossible de libérer le verrou acquis `%s`"

#: glance/registry/api/v1/images.py:134
msgid "Unable to get images"
msgstr "Impossible d'obtenir les images."

#: glance/registry/api/v1/images.py:352
#, python-format
msgid "Unable to show image %s"
msgstr "Impossible d'afficher l'image %s"

#: glance/registry/api/v1/images.py:388
#, python-format
msgid "Unable to delete image %s"
msgstr "Impossible de supprimer l'image %s"

#: glance/registry/api/v1/images.py:440
#, python-format
msgid "Unable to create image %s"
msgstr "Impossible de créer l'image %s"

#: glance/registry/api/v1/images.py:513
#, python-format
msgid "Unable to update image %s"
msgstr "Impossible de mettre à jour l'image %s"

#: glance/tests/functional/v2/test_metadef_resourcetypes.py:98
#, python-format
msgid "Forbidden to create resource type. Reason: %(reason)s"
msgstr "Creation du type de ressource refuse. Raison: %(reason)s "
